2023-11-03 19:19:21,009 [INFO] {utils.py:96} ML Zoomcamp: MID-TERM PROJECT (TWITTER SENTIMENT ANALYSIS)
2023-11-03 19:19:21,009 [INFO] {utils.py:97} start command: C:\Users\ASUS\Documents\GitHub\mlzoomcamp_homeworks\mid-term\src\train.py
2023-11-03 19:19:21,009 [INFO] {utils.py:98} experiment name ..model=rfc..single_experiment
2023-11-03 19:19:21,009 [INFO] {utils.py:99} Namespace(dataset_path='asset', log_folder='logs', logging_steps=100, subsample=-1, save_models=False, model_name='rfc', device=0, seed=42, batch_size=32, experiment_name='', experiment='single_experiment')
2023-11-03 19:19:43,796 [ERROR] {train.py:72} 'CustomDataset' object has no attribute 'data'
Traceback (most recent call last):
  File "C:\Users\ASUS\Documents\GitHub\mlzoomcamp_homeworks\mid-term\src\train.py", line 61, in main
    single_experiment(args, log_dir)
  File "C:\Users\ASUS\Documents\GitHub\mlzoomcamp_homeworks\mid-term\src\train.py", line 47, in single_experiment
    data_context = load_dataset(args)
  File "C:\Users\ASUS\Documents\GitHub\mlzoomcamp_homeworks\mid-term\src\dataloader.py", line 128, in load_dataset
    train_size = int(0.7 * len(dataset))
  File "C:\Users\ASUS\Documents\GitHub\mlzoomcamp_homeworks\mid-term\src\dataloader.py", line 151, in __len__
    return len(self.data)
AttributeError: 'CustomDataset' object has no attribute 'data'
